Workbook

Sheet Login
A1: Project Name | B1: UMPay
A2: Module/Feature Name | B2: Login | P2: HIGH | Q2: MEDIUM | R2: LOW
A3: Reference Document | N3: PASS | O3: =COUNTIF(K:K,"PASS") | P3: =COUNTIFS(K:K,"PASS",L:L,"HIGH") | Q3: =COUNTIFS(K:K,"PASS",L:L,"MEDIUM") | R3: =COUNTIFS(K:K,"PASS",L:L,"LOW")
A4: Created By | B4: KIMA | N4: FAIL | O4: =COUNTIF(K:K,"FAIL") | P4: =COUNTIFS(K:K,"FAIL",L:L,"HIGH") | Q4: =COUNTIFS(K:K,"FAIL",L:L,"MEDIUM") | R4: =COUNTIFS(K:K,"FAIL",L:L,"LOW")
A5: Date of Creation | B5: 46170 | N5: PENDING | O5: =COUNTIF(K:K,"PENDING") | P5: =COUNTIFS(K:K,"PENDING",L:L,"HIGH") | Q5: =COUNTIFS(K:K,"PENDING",L:L,"MEDIUM") | R5: =COUNTIFS(K:K,"PENDING",L:L,"LOW")
A6: Date of Review | B6: 46136
A8: TEST CASE ID | B8: TEST SCENARIO | C8: TEST CASE | D8: TEST CATEGORY | E8: PRE-CONDITION | F8: TEST STEPS | G8: TEST DATA | H8: EXPECTED RESULTS | I8: POST CONDITION | J8: ACTUAL RESULT | K8: STATUS | L8: PRIORITY | M8: TESTER | N8: TEST DATE | O8: DEVICE | P8: BROWSER | Q8: ISSUE LINK | R8: COMMENT | S8: Run
A9: TC_001 | B9: Login Using Email | C9: Successful Login and Logout using email | D9: Positive | E9: User is on Login page. | F9: -Given I log into the UMPay application with valid email credentials using "<row>" of "<excelSheetName>" of "<excelFileName>" -When I check and validate all the homepage contents -Then I should be able to successfully log out | G9: Valid UMPay email credentials | H9: User should be able to login and logout | I9: User is on login page | J9: User can login and logout | K9: PASS | L9: HIGH | N9: 46104 | O9: Window OS | P9: Edge | S9: Run
A10: TC_002 | B10: Login Using Phone | C10: Successful Login and Logout using phone | D10: Positive | E10: User is on Login page. | F10: -I sign in with the phone number in "<row>" of "<excelSheetName>" of "<excelFileName>" -When I check and validate all the homepage contents -Then I should be able to successfully log out | G10: Valid UMPay phone credentials | H10: User should be able to login and logout | I10: User is on login page | J10: User can login and logout | K10: PASS | L10: HIGH | N10: 46104 | O10: Window OS | P10: Edge | S10: Run
A11: TC_003 | B11: Login Using Email | C11: An email address that is not a valid address is rejected before anything is sent | D11: Negative | E11: User is on Login page. | F11: -I am on the UMPay login page -When I try to sign in with the email address in "<row>" of "<excelSheetName>" of "<excelFileName>" -Then the browser should reject the login "email" field with the message in "<row>" of "<excelSheetName>" of "<excelFileName>" -And I should still be on the login page | G11: Invalid email address | H11: User should not be able to login | I11: User is on login page | J11: User can not login | K11: PASS | L11: HIGH | N11: 46104 | O11: Window OS | P11: Edge | S11: Run
A12: TC_004 | B12: Login Using Email | C12: An empty email address cannot be submitted | D12: Negative | E12: User is on Login page. | F12: -I am on the UMPay login page -When I try to sign in with the email address in "<row>" of "<excelSheetName>" of "<excelFileName>" -Then the browser should reject the login "email" field with the message in "<row>" of "<excelSheetName>" of "<excelFileName>" -And I should still be on the login page | G12: Invalid email address | H12: User should not be able to login | I12: User is on login page | J12: User can not login | K12: PASS | L12: HIGH | N12: 46104 | O12: Window OS | P12: Edge | S12: Run
A13: TC_005 | B13: Login Using Email | C13: An email address nobody holds is turned away by the server | D13: Negative | E13: User is on Login page. | F13: -I am on the UMPay login page -When I try to sign in with the email address in "<row>" of "<excelSheetName>" of "<excelFileName>" -Then the sign in should be refused with the message in "<row>" of "<excelSheetName>" of "<excelFileName>" -And I should still be on the login page | G13: Invalid email address | H13: User should not be able to login | I13: User is on login page | J13: User can not login | K13: PASS | L13: HIGH | N13: 46104 | O13: Window OS | P13: Edge | S13: Run
A14: TC_006 | B14: Login Using Email | C14: A password under six characters is refused | D14: Negative | E14: User is on Login page. | F14: -I am on the UMPay login page -When I try to sign in with the email address in "<row>" of "<excelSheetName>" of "<excelFileName>" -Then the form should complain with the message in "<row>" of "<excelSheetName>" of "<excelFileName>" -And I should still be on the login page | G14: Invalid email address | H14: User should not be able to login | I14: User is on login page | J14: User can not login | K14: PASS | L14: HIGH | N14: 46104 | O14: Window OS | P14: Edge | S14: Run
A15: TC_007 | B15: Login Using Email | C15: An empty password cannot be submitted | D15: Negative | E15: User is on Login page. | F15: -I am on the UMPay login page -When I try to sign in with the email address in "<row>" of "<excelSheetName>" of "<excelFileName>" -Then the browser should reject the login "password" field with the message in "<row>" of "<excelSheetName>" of "<excelFileName>" -And I should still be on the login page | G15: Invalid email address | H15: User should not be able to login | I15: User is on login page | J15: User can not login | K15: PASS | L15: HIGH | N15: 46104 | O15: Window OS | P15: Edge | S15: Run
A16: TC_008 | B16: Login Using Phone | C16: A phone number that is not a number is rejected before anything is sent | D16: Negative | E16: User is on Login page. | F16: -I am on the UMPay login page -When I try to sign in with the phone number in "<row>" of "<excelSheetName>" of "<excelFileName>" -Then the browser should reject the login "phone" field with the message in "<row>" of "<excelSheetName>" of "<excelFileName>" -And I should still be on the login page | G16: Invalid phone number | H16: User should not be able to login | I16: User is on login page | J16: User can not login | K16: PASS | L16: HIGH | N16: 46104 | O16: Window OS | P16: Edge | S16: Run
A17: TC_009 | B17: Login Using Phone | C17: An empty phone number cannot be submitted | D17: Negative | E17: User is on Login page. | F17: -I am on the UMPay login page -When I try to sign in with the phone number in "<row>" of "<excelSheetName>" of "<excelFileName>" -Then the browser should reject the login "phone" field with the message in "<row>" of "<excelSheetName>" of "<excelFileName>" -And I should still be on the login page | G17: Invalid phone number | H17: User should not be able to login | I17: User is on login page | J17: User can not login | K17: PASS | L17: HIGH | N17: 46104 | O17: Window OS | P17: Edge | S17: Run
A18: TC_010 | B18: Login Using Phone | C18: A phone number shorter than six digits is refused | D18: Negative | E18: User is on Login page. | F18: -I am on the UMPay login page -When I try to sign in with the phone number in "<row>" of "<excelSheetName>" of "<excelFileName>" -Then the sign in should be refused with the message in "<row>" of "<excelSheetName>" of "<excelFileName>" -And I should still be on the login page | G18: Invalid phone number | H18: User should not be able to login | I18: User is on login page | J18: User can not login | K18: PASS | L18: HIGH | N18: 46104 | O18: Window OS | P18: Edge | S18: Run
A19: TC_011 | B19: Login Using Phone | C19: A phone number nobody holds is turned away by the server | D19: Negative | E19: User is on Login page. | F19: -I am on the UMPay login page -When I try to sign in with the phone number in "<row>" of "<excelSheetName>" of "<excelFileName>" -Then the sign in should be refused with the message in "<row>" of "<excelSheetName>" of "<excelFileName>" -And I should still be on the login page | G19: Invalid phone number | H19: User should not be able to login | I19: User is on login page | J19: User can not login | K19: PASS | L19: HIGH | N19: 46104 | O19: Window OS | P19: Edge | S19: Run
A20: TC_012 | B20: Login Using Phone | C20: The phone box keeps a leading zero | D20: Negative | E20: User is on Login page. | F20: -I am on the UMPay login page -When I enter the phone number in "<row>" of "<excelSheetName>" of "<excelFileName>" without signing in -Then the phone number should be kept as typed in "<row>" of "<excelSheetName>" of "<excelFileName>" | G20: Invalid phone number | H20: User should not be able to login | I20: User is on login page | J20: User can not login | K20: PASS | L20: HIGH | N20: 46104 | O20: Window OS | P20: Edge | S20: Run
... A23: TC_015 | B23: Login Using Phone | C23: Three wrong passwords in a row lock the account | D23: Negative | E23: User is on Login page. | F23: -I am on the UMPay login page -When I try to sign in with the email address in "<row>" of "<excelSheetName>" of "<excelFileName>" -And I try to sign in with the email address in "<row>" of "<excelSheetName>" of "<excelFileName>" -And I try to sign in with the email address in "<row>" of "<excelSheetName>" of "<excelFileName>" | G23: Valid UMPay | H23: User should not be able to login | I23: User is on login page | J23: User can not login | K23: PASS | L23: HIGH | N23: 46104 | O23: Window OS | P23: Edge | S23: Run
A24: TC_016 | B24: Login | C24: Forgot password reaches the reset page | D24: Positive | E24: User is on the login page | F24: -Given I am on the UMPay "<page>" page -When I follow the Forgot password link -Then the password reset page should open | G24: No account needed | H24: The Forgot password link should open the password reset page, since somebody locked out of their account has to be able to reach it without signing in | I24: User is on the password reset page | J24: The Forgot password link opened the password reset page | K24: PASS | L24: HIGH | M24: KIMA | N24: 46273 | O24: Window OS | P24: Chromium | S24: Run
A25: TC_017 | B25: Login | C25: A new user can reach registration from the login page | D25: Positive | E25: User is on the login page | F25: -Given I am on the UMPay "<page>" page -When I follow the Register link -Then the registration page should open | G25: No account needed | H25: The Register link should open the registration page, so somebody without an account can get one from where they landed | I25: User is on the registration page | J25: The Register link opened the registration page | K25: PASS | L25: MEDIUM | M25: KIMA | N25: 46273 | O25: Window OS | P25: Chromium | S25: Run
A26: TC_018 | B26: Login | C26: Customer Service can be reached without signing in | D26: Positive | E26: User is on the login page | F26: -Given I am on the UMPay "<page>" page -When I open Customer Service from the login page -Then the customer service chat should open | G26: No account needed | H26: The support bubble should open the chat without signing in, since somebody who cannot sign in is exactly who needs to reach support | I26: The customer service chat is open | J26: Pressing the support bubble opened the customer service chat, which is served as a separate application in an iframe. Worth noting about the page itself: two buttons are pinned to that corner, and the second declares z-index 9999 yet is drawn underneath the first, whose image overlaps it - so anything addressing that second button is intercepted every time | K26: PASS | L26: HIGH | M26: KIMA | N26: 46273 | O26: Window OS | P26: Chromium | S26: Run

Sheet Register
A1: Project Name | B1: UMPay
A2: Module/Feature Name | B2: Register | P2: HIGH | Q2: MEDIUM | R2: LOW
A3: Reference Document | N3: PASS | O3: =COUNTIF(K:K,"PASS") | P3: =COUNTIFS(K:K,"PASS",L:L,"HIGH") | Q3: =COUNTIFS(K:K,"PASS",L:L,"MEDIUM") | R3: =COUNTIFS(K:K,"PASS",L:L,"LOW")
A4: Created By | B4: KIMA | N4: FAIL | O4: =COUNTIF(K:K,"FAIL") | P4: =COUNTIFS(K:K,"FAIL",L:L,"HIGH") | Q4: =COUNTIFS(K:K,"FAIL",L:L,"MEDIUM") | R4: =COUNTIFS(K:K,"FAIL",L:L,"LOW")
A5: Date of Creation | B5: 46170 | N5: PENDING | O5: =COUNTIF(K:K,"PENDING") | P5: =COUNTIFS(K:K,"PENDING",L:L,"HIGH") | Q5: =COUNTIFS(K:K,"PENDING",L:L,"MEDIUM") | R5: =COUNTIFS(K:K,"PENDING",L:L,"LOW")
A6: Date of Review | B6: 46170
A8: TEST CASE ID | B8: TEST SCENARIO | C8: TEST CASE | D8: TEST CATEGORY | E8: PRE-CONDITION | F8: TEST STEPS | G8: TEST DATA | H8: EXPECTED RESULTS | I8: POST CONDITION | J8: ACTUAL RESULT | K8: STATUS | L8: PRIORITY | M8: TESTER | N8: TEST DATE | O8: DEVICE | P8: BROWSER | Q8: ISSUE LINK | R8: COMMENT | S8: Run
A9: TC_001 | B9: Registration | C9: Successful registration with a new email address | D9: Positive | E9: User is on Register Page. | F9: -When I register with an email address using "<row>" of "<excelSheetName>" of "<excelFileName>" -And I enter the verification code sent to the email address -Then the registration should be accepted -When I accept the policies shown to a new account -And I set a PIN security code -And I skip the two factor authentication prompt -Then I should land on the UMPay home page -And I should see the account wallets on the home page | G9: Valid email address | H9: User should be able to register successfully | I9: User is registered | J9: User can register successfully | K9: PASS | L9: HIGH | M9: KIMA | O9: Window OS | P9: Edge | S9: Run
A10: TC_002 | B10: Registration | C10: Successful registration with a phone number | D10: Positive | E10: User is on Register Page. | F10: -When I register with a phone number using "<row>" of "<excelSheetName>" of "<excelFileName>" -Then the registration should reach the phone verification step | G10: Valid phone number | H10: User should be able to register successfully | I10: User is registered | J10: User can register successfully | K10: PASS | L10: HIGH | M10: KIMA | O10: Window OS | P10: Edge | S10: Run
A11: TC_003 | B11: Registration | C11: Registration is rejected for an email address that is already in use | D11: Negative | E11: User is on Register Page. | F11: -When I register with an email address using "<row>" of "<excelSheetName>" of "<excelFileName>" -Then the registration should be rejected with the message in "<row>" of "<excelSheetName>" of "<excelFileName>" | G11: Email already used | H11: User should not be able to register | I11: User is not registered | J11: User can not register | K11: PASS | L11: HIGH | M11: KIMA | O11: Window OS | P11: Edge | S11: Run
A12: TC_004 | B12: Registration | C12: Registration is rejected for phone number that is already in use | D12: Negative | E12: User is on Register Page. | F12: -When I register with a phone number using "<row>" of "<excelSheetName>" of "<excelFileName>" -Then the registration should be rejected with the message in "<row>" of "<excelSheetName>" of "<excelFileName>" | G12: Phone number already used | H12: User should not be able to register | I12: User is not registered | J12: User can not register | K12: PASS | L12: HIGH | M12: KIMA | O12: Window OS | P12: Edge | S12: Run
A13: TC_005 | B13: Registration | C13: Registration is rejected when the captcha code is wrong | D13: Negative | E13: User is on Register Page. | F13: -When I register with an email address using "<row>" of "<excelSheetName>" of "<excelFileName>" -Then the registration should be rejected with the message in "<row>" of "<excelSheetName>" of "<excelFileName>" | G13: Any valid email or phone number | H13: User should not be able to register | I13: User is not registered | J13: User can not register | K13: PASS | L13: HIGH | M13: KIMA | O13: Window OS | P13: Edge | S13: Run
A14: TC_006 | B14: Registration | C14: Registration is blocked when the password is shorter than six characters | D14: Negative | E14: User is on Register Page. | F14: -When I fill the registration form using "<row>" of "<excelSheetName>" of "<excelFileName>" without submitting it -Then the browser should reject the "password" field with the message "Must be at least 6 characters alphanumeric!" | G14: Any valid email or phone number | H14: User should not be able to register | I14: User is not registered | J14: User can not register | K14: PASS | L14: HIGH | M14: KIMA | O14: Window OS | P14: Edge | S14: Run
A15: TC_007 | B15: Register | C15: Existing users can navigate to the login page from the registration page | D15: Positive | E15: User is on the registration page | F15: -Given I am on the UMPay "<page>" page -Then I should be able to go to the login page from the registration page | G15: No account needed | H15: The registration page should offer a way back to the login page for somebody who already has an account | I15: User is on the login page | J15: The link on the registration page opened the login page | K15: PASS | L15: MEDIUM | M15: KIMA | N15: 46273 | O15: Window OS | P15: Chromium | S15: Run

Sheet Reset_Password
A1: Project Name | B1: UMPay
A2: Module/Feature Name | B2: Reset Password | P2: HIGH | Q2: MEDIUM | R2: LOW
A3: Reference Document | N3: PASS | O3: =COUNTIF(K:K,"PASS") | P3: =COUNTIFS(K:K,"PASS",L:L,"HIGH") | Q3: =COUNTIFS(K:K,"PASS",L:L,"MEDIUM") | R3: =COUNTIFS(K:K,"PASS",L:L,"LOW")
A4: Created By | B4: KIMA | N4: FAIL | O4: =COUNTIF(K:K,"FAIL") | P4: =COUNTIFS(K:K,"FAIL",L:L,"HIGH") | Q4: =COUNTIFS(K:K,"FAIL",L:L,"MEDIUM") | R4: =COUNTIFS(K:K,"FAIL",L:L,"LOW")
A5: Date of Creation | B5: 46170 | N5: PENDING | O5: =COUNTIF(K:K,"PENDING") | P5: =COUNTIFS(K:K,"PENDING",L:L,"HIGH") | Q5: =COUNTIFS(K:K,"PENDING",L:L,"MEDIUM") | R5: =COUNTIFS(K:K,"PENDING",L:L,"LOW")
A6: Date of Review | B6: 46136
A8: TEST CASE ID | B8: TEST SCENARIO | C8: TEST CASE | D8: TEST CATEGORY | E8: PRE-CONDITION | F8: TEST STEPS | G8: TEST DATA | H8: EXPECTED RESULTS | I8: POST CONDITION | J8: ACTUAL RESULT | K8: STATUS | L8: PRIORITY | M8: TESTER | N8: TEST DATE | O8: DEVICE | P8: BROWSER | Q8: ISSUE LINK | R8: COMMENT | S8: Run
A9: TC_001 | B9: Reset Password | C9: The reset form refuses a phone number that is not a number | D9: Positive | E9: -User is on Reset Password Page | F9: -I am on the UMPay password reset page -When I fill the phone reset form from "<row>" of "<excelSheetName>" of "<excelFileName>" without sending it -And I send the reset form -Then the reset form should complain with the message in "<row>" of "<excelSheetName>" of "<excelFileName>" -And the reset form should still be shown | G9: Invalid Phone Number | H9: User should not be able to reset | I9: User is still on Reset Password Page. | J9: User can not reset | K9: PASS | L9: HIGH | M9: KIMA | N9: 46104 | O9: Window OS | P9: Edge | S9: Run
A10: TC_002 | B10: Reset Password | C10: The reset form cannot be sent without a phone number | D10: Positive | E10: -User is on Reset Password Page | F10: -I am on the UMPay password reset page When I fill the phone reset form from "<row>" of "<excelSheetName>" of "<excelFileName>" without sending it And I send the reset form Then the browser should reject the reset "phone" field with the message in "<row>" of "<excelSheetName>" of "<excelFileName>" And the reset form should still be shown | G10: Invalid Phone Number | H10: User should not be able to reset | I10: User is still on Reset Password Page. | J10: User can not reset | K10: PASS | L10: HIGH | M10: KIMA | N10: 46104 | O10: Window OS | P10: Edge | S10: Run
A11: TC_003 | B11: Reset Password | C11: The reset phone box keeps a leading zero | D11: Positive | E11: -User is on Reset Password Page | F11: -I am on the UMPay password reset page -When I fill the phone reset form from "<row>" of "<excelSheetName>" of "<excelFileName>" without sending it -Then the reset phone number should be kept as typed in "<row>" of "<excelSheetName>" of "<excelFileName>" | G11: Valid UNCS Admin credentials. | H11: User should not be able to reset | I11: User is still on Reset Password Page. | J11: User can not reset | K11: PASS | L11: HIGH | M11: KIMA | N11: 46104 | O11: Window OS | P11: Edge | S11: Run
A12: TC_004 | B12: Reset Password | C12: The reset form cannot be sent without a captcha | D12: Positive | E12: -User is on Reset Password Page | F12: -I am on the UMPay password reset page -When I fill the phone reset form from "<row>" of "<excelSheetName>" of "<excelFileName>" without sending it -And I send the reset form -Then the browser should reject the reset "captcha" field with the message in "<row>" of "<excelSheetName>" of "<excelFileName>" -And the reset form should still be shown | G12: Valid UNCS Admin credentials. | H12: User should not be able to reset | I12: User is still on Reset Password Page. | J12: User can not reset | K12: PASS | L12: HIGH | M12: KIMA | N12: 46104 | O12: Window OS | P12: Edge | S12: Run
A13: TC_005 | B13: Reset Password | C13: The email reset form cannot be sent without a captcha either | D13: Positive | E13: -User is on Reset Password Page | F13: -I am on the UMPay password reset page -When I fill the email reset form from "<row>" of "<excelSheetName>" of "<excelFileName>" without sending it -And I send the reset form -Then the browser should reject the reset "captcha" field with the message in "<row>" of "<excelSheetName>" of "<excelFileName>" -And the reset form should still be shown | G13: Valid UNCS Admin credentials. | H13: User should not be able to reset | I13: User is still on Reset Password Page. | J13: User can not reset | K13: PASS | L13: HIGH | M13: KIMA | N13: 46104 | O13: Window OS | P13: Edge | S13: Run
A14: TC_006 | B14: Reset Password | C14: The reset form refuses an email address that is not a valid address | D14: Positive | E14: -User is on Reset Password Page | F14: -I am on the UMPay password reset page -When I fill the email reset form from "<row>" of "<excelSheetName>" of "<excelFileName>" without sending it -And I send the reset form -Then the browser should reject the reset "email" field with the message in "<row>" of "<excelSheetName>" of "<excelFileName>" -And the reset form should still be shown | G14: Valid UNCS Admin credentials. | H14: User should not be able to reset | I14: User is still on Reset Password Page. | J14: User can not reset | K14: PASS | L14: HIGH | M14: KIMA | N14: 46104 | O14: Window OS | P14: Edge | S14: Run
A15: TC_007 | B15: Reset Password | C15: A new captcha can be asked for on the phone reset form | D15: Positive | E15: -User is on Reset Password Page | F15: -I am on the UMPay password reset page -When I ask the reset form for a new captcha -Then a different captcha image should be shown | G15: Valid UNCS Admin credentials. | H15: User should not be able to reset | I15: User is still on Reset Password Page. | J15: User can not reset | K15: PASS | L15: HIGH | M15: KIMA | N15: 46104 | O15: Window OS | P15: Edge | S15: Run
A16: TC_008 | B16: Reset Password | C16: A new captcha can be asked for on the email reset form | D16: Positive | E16: -User is on Reset Password Page | F16: -I am on the UMPay password reset page -When I fill the email reset form from "<row>" of "<excelSheetName>" of "<excelFileName>" without sending it -And I ask the reset form for a new captcha -Then a different captcha image should be shown | G16: Valid UNCS Admin credentials. | H16: User should not be able to reset | I16: User is still on Reset Password Page. | J16: User can not reset | K16: PASS | L16: HIGH | M16: KIMA | N16: 46104 | O16: Window OS | P16: Edge | S16: Run
A17: TC_009 | B17: Reset Password | C17: A wrong captcha is refused on the phone reset form | D17: Negative | E17: -User is on Reset Password Page | F17: -I am on the UMPay password reset page -When I ask to reset the password by phone using "<row>" of "<excelSheetName>" of "<excelFileName>" -Then the reset should be refused with the message in "<row>" of "<excelSheetName>" of "<excelFileName>" -And the reset form should still be shown | G17: Valid UNCS Admin credentials. | H17: User should not be able to reset | I17: User is still on Reset Password Page. | J17: User can not reset | K17: PASS | L17: HIGH | M17: KIMA | N17: 46104 | O17: Window OS | P17: Edge | S17: Run
A18: TC_010 | B18: Reset Password | C18: A wrong captcha is refused on the email reset form | D18: Negative | E18: -User is on Reset Password Page | F18: -I am on the UMPay password reset page -When I ask to reset the password by email using "<row>" of "<excelSheetName>" of "<excelFileName>" -Then the reset should be refused with the message in "<row>" of "<excelSheetName>" of "<excelFileName>" -And the reset form should still be shown | G18: Valid UNCS Admin credentials. | H18: User should not be able to reset | I18: User is still on Reset Password Page. | J18: User can not reset | K18: PASS | L18: HIGH | M18: KIMA | N18: 46104 | O18: Window OS | P18: Edge | S18: Run
A19: TC_011 | B19: Reset Password | C19: A phone number shorter than six digits gets no reset | D19: Negative | E19: -User is on Reset Password Page | F19: -I am on the UMPay password reset page -When I ask to reset the password by phone using "<row>" of "<excelSheetName>" of "<excelFileName>" -Then the reset should be refused with the message in "<row>" of "<excelSheetName>" of "<excelFileName>" -And the reset form should still be shown | G19: Valid UNCS Admin credentials. | H19: User should not be able to reset | I19: User is still on Reset Password Page. | J19: User can not reset | K19: PASS | L19: HIGH | M19: KIMA | N19: 46104 | O19: Window OS | P19: Edge | S19: Run
A20: TC_012 | B20: Reset Password | C20: A phone number nobody holds learns nothing about itself | D20: Negative | E20: -User is on Reset Password Page | F20: -I am on the UMPay password reset page -When I ask to reset the password by phone using "<row>" of "<excelSheetName>" of "<excelFileName>" -Then the verification step should be reached | G20: Valid UNCS Admin credentials. | H20: User should not be able to reset | I20: User is still on Reset Password Page. | J20: User can not reset | K20: PASS | L20: HIGH | M20: KIMA | N20: 46104 | O20: Window OS | P20: Edge | S20: Run
... A24: TC_016 | B24: Reset Password | C24: Going back from the verification step should return to the form | D24: Negative | E24: User is on the password reset page | F24: -Given I am on the UMPay password reset page -When I ask to reset the password by email using "<row>" of "<excelSheetName>" of "<excelFileName>" -Then the verification step should be reached -When I go back from the verification step -Then the reset form should be shown again | G24: Email: the registered address | H24: Going back from the verification step should return to the reset form rather than stranding somebody who mistyped their address | I24: User is on the reset form | J24: COULD NOT BE RUN - the platform answered the one-time-code request with 400 "Too Many Requests" (POST /api/notification/otp), so the verification step was never reached and going back from it could not be tried. This says nothing about the application either way; the account has simply asked for too many codes today. To be re-run once the limit clears | K24: PENDING | L24: MEDIUM | M24: KIMA | N24: 46273 | O24: Window OS | P24: Chromium | S24: Run

Sheet Deposit
A1: Project Name | B1: UMPay
A2: Module/Feature Name | B2: Deposit | P2: HIGH | Q2: MEDIUM | R2: LOW
A3: Reference Document | N3: PASS | O3: =COUNTIF(K:K,"PASS") | P3: =COUNTIFS(K:K,"PASS",L:L,"HIGH") | Q3: =COUNTIFS(K:K,"PASS",L:L,"MEDIUM") | R3: =COUNTIFS(K:K,"PASS",L:L,"LOW")
A4: Created By | B4: KIMA | N4: FAIL | O4: =COUNTIF(K:K,"FAIL") | P4: =COUNTIFS(K:K,"FAIL",L:L,"HIGH") | Q4: =COUNTIFS(K:K,"FAIL",L:L,"MEDIUM") | R4: =COUNTIFS(K:K,"FAIL",L:L,"LOW")
A5: Date of Creation | B5: 46170 | N5: PENDING | O5: =COUNTIF(K:K,"PENDING") | P5: =COUNTIFS(K:K,"PENDING",L:L,"HIGH") | Q5: =COUNTIFS(K:K,"PENDING",L:L,"MEDIUM") | R5: =COUNTIFS(K:K,"PENDING",L:L,"LOW")
A6: Date of Review | B6: 46170
A8: TEST CASE ID | B8: TEST SCENARIO | C8: TEST CASE | D8: TEST CATEGORY | E8: PRE-CONDITION | F8: TEST STEPS | G8: TEST DATA | H8: EXPECTED RESULTS | I8: POST CONDITION | J8: ACTUAL RESULT | K8: STATUS | L8: PRIORITY | M8: TESTER | N8: TEST DATE | O8: DEVICE | P8: BROWSER | Q8: ISSUE LINK | R8: COMMENT | S8: Run
A9: TC_001 | B9: Deposit | C9: Successful Deposit Transaction | D9: Positive | E9: User is on Deposit page | F9: -Given I log into the UMPay application with valid email credentials using "<row>" of "<excelSheetName>" of "<excelFileName>" -When I navigate to Deposit page -Then I should be able to initiate a deposit transaction using "<row>" of "<excelSheetName>" of "<excelFileName>" | G9: Valid UMPay credentials | H9: User should be able to perform deposit successfully | I9: User is navigated back to home screen | J9: User can perform deposit successfully | K9: PASS | L9: HIGH | M9: KIMA | O9: Window OS | P9: Edge | S9: Run
A10: TC_002 | B10: Deposit | C10: The deposit form offers a wallet for every currency the account holds | D10: Positive | E10: User is on Deposit page | F10: -I log into the UMPay application with valid email credentials using "1" of "sheet1" of "Deposit_TestData.xlsx" -When I navigate to Deposit page -Then the deposit currency list should offer "BDT, BRL, HKD, IDR, MXN, MYR, PHP, THB, USD, VND" | G10: Valid UMPay credentials | H10: User should be able to see all the currency wallet | I10: User is still on Deposit page | J10: User can see all the currency wallet | K10: PASS | L10: HIGH | M10: KIMA | O10: Window OS | P10: Edge | S10: Run
A11: TC_003 | B11: Deposit | C11: An amount below the minimum is refused | D11: Negative | E11: User is on Deposit page | F11: -Given I log into the UMPay application with valid email credentials using "1" of "sheet1" of "Deposit_TestData.xlsx" -When I navigate to Deposit page -And I choose the "HKD" wallet on the Deposit page -And I enter "50" as the deposit amount -Then the deposit amount should be refused with "Please input an amount of limit min or above!" | G11: Valid UMPay credentials | H11: User should not be able to deposit amount lower than limit | I11: User is still on Deposit page | J11: User can not deposit amount lower than limit | K11: PASS | L11: HIGH | M11: KIMA | O11: Window OS | P11: Edge | S11: Run
A12: TC_004 | B12: Deposit | C12: An amount above the maximum is refused | D12: Negative | E12: User is on Deposit page | F12: -I log into the UMPay application with valid email credentials using "1" of "sheet1" of "Deposit_TestData.xlsx" -When I navigate to Deposit page -And I choose the "HKD" wallet on the Deposit page -And I enter "1000000000" as the deposit amount -Then the deposit amount should be refused with "Please input an amount of limit max or below!" | G12: Valid UMPay credentials | H12: User should not be able to deposit amount greater than limit | I12: User is still on Deposit page | J12: User can not deposit amount greater than limit | K12: PASS | L12: HIGH | M12: KIMA | O12: Window OS | P12: Edge | S12: Run
A13: TC_005 | B13: Deposit | C13: The minimum itself is accepted | D13: Positive | E13: User is on Deposit page | F13: -I log into the UMPay application with valid email credentials using "1" of "sheet1" of "Deposit_TestData.xlsx" -When I navigate to Deposit page -And I choose the "HKD" wallet on the Deposit page -And I enter "100" as the deposit amount -Then the deposit amount should be accepted | G13: Valid UMPay credentials | H13: User should be able to perform deposit successfully | I13: User is navigated back to home screen | J13: User can perform deposit successfully | K13: PASS | L13: HIGH | M13: KIMA | O13: Window OS | P13: Edge | S13: Run
A14: TC_006 | B14: Deposit | C14: The amount box states the limits it enforces | D14: Positive | E14: User is on Deposit page | F14: -I log into the UMPay application with valid email credentials using "1" of "sheet1" of "Deposit_TestData.xlsx" -When I navigate to Deposit page -And I choose the "HKD" wallet on the Deposit page -Then the deposit form should state a minimum of "100" and a maximum of "999999999" | G14: Valid UMPay credentials | H14: User should be able to perform deposit successfully | I14: User is navigated back to home screen | J14: User can perform deposit successfully | K14: PASS | L14: HIGH | M14: KIMA | O14: Window OS | P14: Edge | S14: Run

Sheet Withdraw
A1: Project Name | B1: UMPay
A2: Module/Feature Name | B2: Withdraw | P2: HIGH | Q2: MEDIUM | R2: LOW
A3: Reference Document | N3: PASS | O3: =COUNTIF(K:K,"PASS") | P3: =COUNTIFS(K:K,"PASS",L:L,"HIGH") | Q3: =COUNTIFS(K:K,"PASS",L:L,"MEDIUM") | R3: =COUNTIFS(K:K,"PASS",L:L,"LOW")
A4: Created By | B4: KIMA | N4: FAIL | O4: =COUNTIF(K:K,"FAIL") | P4: =COUNTIFS(K:K,"FAIL",L:L,"HIGH") | Q4: =COUNTIFS(K:K,"FAIL",L:L,"MEDIUM") | R4: =COUNTIFS(K:K,"FAIL",L:L,"LOW")
A5: Date of Creation | B5: 46170 | N5: PENDING | O5: =COUNTIF(K:K,"PENDING") | P5: =COUNTIFS(K:K,"PENDING",L:L,"HIGH") | Q5: =COUNTIFS(K:K,"PENDING",L:L,"MEDIUM") | R5: =COUNTIFS(K:K,"PENDING",L:L,"LOW")
A6: Date of Review | B6: 46170
A8: TEST CASE ID | B8: TEST SCENARIO | C8: TEST CASE | D8: TEST CATEGORY | E8: PRE-CONDITION | F8: TEST STEPS | G8: TEST DATA | H8: EXPECTED RESULTS | I8: POST CONDITION | J8: ACTUAL RESULT | K8: STATUS | L8: PRIORITY | M8: TESTER | N8: TEST DATE | O8: DEVICE | P8: BROWSER | Q8: ISSUE LINK | R8: COMMENT | S8: Run
A9: TC_001 | B9: Withdraw | C9: Successful Withdraw Transaction using Template | D9: Positive | E9: User is on Withdraw page | F9: -Given I log into the UMPay application with valid email credentials using "<row>" of "<excelSheetName>" of "<excelFileName>" -When I navigate to Withdraw page -Then I should be able to initiate a withdraw transaction using "<row>" of "<excelSheetName>" of "<excelFileName>" | G9: Valid UNCS Admin credentials. | H9: User should be able to submit withdraw transaction successfully | I9: User is navigated to home page | J9: User can submit withdraw transaction successfully | K9: PASS | L9: HIGH | M9: KIMA | O9: Window OS | P9: Edge | S9: Run
A10: TC_002 | B10: Withdraw | C10: Successful Withdraw Transaction using New Account | D10: Positive | E10: User is on Withdraw page | F10: -Given I log into the UMPay application with valid email credentials using "<row>" of "<excelSheetName>" of "<excelFileName>" -When I navigate to Withdraw page -Then I should be able to initiate a withdraw transaction using "<row>" of "<excelSheetName>" of "<excelFileName>" | G10: Valid UNCS Admin credentials. | H10: User should be able to submit withdraw transaction successfully | I10: User is navigated to home page | J10: User can submit withdraw transaction successfully | K10: PASS | L10: HIGH | M10: KIMA | O10: Window OS | P10: Edge | S10: Run
A11: TC_003 | B11: Withdraw | C11: The withdraw form offers a wallet for every currency the account holds | D11: Positive | E11: User is on Withdraw page | F11: -Given I log into the UMPay application with valid email credentials using "<row>" of "<excelSheetName>" of "<excelFileName>" -When I navigate to Withdraw page -Then the withdraw currency list should offer "BDT, BRL, HKD, IDR, MXN, MYR, PHP, THB, USD, VND" | G11: Valid UNCS Admin credentials. | H11: User should be able to see all the wallets | I11: User is still on Withdraw page | J11: User can see all the wallets | K11: PASS | L11: HIGH | M11: KIMA | O11: Window OS | P11: Edge | S11: Run
A12: TC_004 | B12: Withdraw | C12: The amount box holds each wallet to its own stated limits | D12: Positive | E12: User is on Withdraw page | F12: -Given I log into the UMPay application with valid email credentials using "1" of "sheet1" of "Withdraw_TestData.xlsx" -When I navigate to Withdraw page -And I choose the "<currency>" wallet on the Withdraw page -And I enter one below the stated minimum as the withdraw amount -Then the withdraw amount should be refused with "Please input an amount of limit min or above!" -When I enter one above the stated maximum as the withdraw amount -Then the withdraw amount should be refused with "Please input an amount of limit max or below!" -When I enter the stated minimum as the withdraw amount -Then the withdraw amount should be accepted | G12: Valid UNCS Admin credentials. | H12: Amount limits should work as expected | I12: User is still on Withdraw page | J12: Amount limits are working as expected | K12: PASS | L12: HIGH | M12: KIMA | O12: Window OS | P12: Edge | S12: Run
A13: TC_005 | B13: Withdraw | C13: The amount box refuses anything that is not an amount | D13: Negative | E13: User is on the Withdraw page with the HKD wallet chosen | F13: -Given I log into the UMPay application with valid email credentials using "1" of "sheet1" of "Withdraw_TestData.xlsx" -When I navigate to Withdraw page -And I choose the "HKD" wallet on the Withdraw page -And I type "<typed>" at the withdraw amount box -Then the withdraw amount box should be left holding nothing -And the withdraw amount should be refused with "This field is required" | G13: Amount: abcd, 0, -100 | H13: None of these should be accepted as an amount, and the form should say the field is required rather than leaving something unpayable sitting in the box | I13: User is on the Withdraw page | J13: None of the three ever reached the box. "abcd", "0" and "-100" each left it holding nothing at all, and the form answered "This field is required" - so the form works on the box as it is typed rather than letting a wrong amount sit in it | K13: PASS | L13: HIGH | M13: KIMA | N13: 46273 | O13: Window OS | P13: Chromium | S13: Run
A14: TC_006 | B14: Withdraw | C14: The amount box will not take a figure finer than the currency pays in | D14: Negative | E14: User is on the Withdraw page with the HKD wallet chosen | F14: -Given I log into the UMPay application with valid email credentials using "1" of "sheet1" of "Withdraw_TestData.xlsx" -When I navigate to Withdraw page -And I choose the "HKD" wallet on the Withdraw page -And I type "<typed>" at the withdraw amount box -Then the withdraw amount box should be left holding "<kept>" | G14: Amount: 100.555 | H14: The box should keep only what the currency can be paid in - Hong Kong dollars have cents and nothing smaller | I14: User is on the Withdraw page | J14: Typing 100.555 left the box holding 100.55, so the form keeps only what Hong Kong dollars can actually be paid in | K14: PASS | L14: MEDIUM | M14: KIMA | N14: 46273 | O14: Window OS | P14: Chromium | S14: Run
A15: TC_007 | B15: Withdraw | C15: A withdraw cannot be confirmed with nowhere to send the money | D15: Negative | E15: User is on the Withdraw page with the HKD wallet chosen | F15: -Given I log into the UMPay application with valid email credentials using "1" of "sheet1" of "Withdraw_TestData.xlsx" -When I navigate to Withdraw page -And I choose the "<currency>" wallet on the Withdraw page -And I enter the stated minimum as the withdraw amount -Then the withdraw should not be confirmable -When I choose the saved payout account "<account>" -Then the withdraw should be confirmable | G15: Amount: the stated minimum; Payout account: none, then HSBC | H15: Confirm should not be pressable while no payout account has been chosen, and choosing one should be what makes it pressable | I15: User is on the Withdraw page | J15: With 100 HKD entered and no payout account chosen, Confirm was disabled and could not be pressed. Choosing the saved HSBC account is what made it pressable, so the payout account is what was stopping it rather than something else on the form | K15: PASS | L15: HIGH | M15: KIMA | N15: 46273 | O15: Window OS | P15: Chromium | S15: Run
A16: TC_008 | B16: Withdraw | C16: A withdraw for more than the wallet holds is refused | D16: Negative | E16: User is on the Withdraw page with the HKD wallet chosen | F16: -Given I log into the UMPay application with valid email credentials using "1" of "sheet1" of "Withdraw_TestData.xlsx" -When I navigate to Withdraw page -And I choose the "<currency>" wallet on the Withdraw page -And I enter more than the wallet holds as the withdraw amount -And I choose the saved payout account "<account>" -And I confirm the withdraw -Then the platform should refuse to raise the order | G16: Amount: a thousand more than the wallet holds; Payout account: HSBC | H16: The platform should refuse to raise the order and say why, so somebody withdrawing from their own wallet is told they are short rather than left pressing Confirm | I16: No order is raised and the wallet is untouched | J16: DEFECT - the HKD wallet held HK$8,156.51 and the form was asked for 9,156 with the saved HSBC account chosen. Confirm was enabled, it was pressed, and then nothing happened at all: no PIN was asked for, no order was raised, no dialog, no notice, no message of any kind. The network confirms nothing was even attempted - the last call the page made was the fee lookup /api/fee/payment/PM134081?currency=HKD&amount=9156, and no withdraw was ever posted. The money is safe, but somebody withdrawing from their own wallet is left pressing a button that silently does nothing and is never told they are short | K16: FAIL | L16: HIGH | M16: KIMA | N16: 46273 | O16: Window OS | P16: Chromium | S16: Run

Sheet Transfer
A1: Project Name | B1: UMPay
A2: Module/Feature Name | B2: Transfer | P2: HIGH | Q2: MEDIUM | R2: LOW
A3: Reference Document | N3: PASS | O3: =COUNTIF(K:K,"PASS") | P3: =COUNTIFS(K:K,"PASS",L:L,"HIGH") | Q3: =COUNTIFS(K:K,"PASS",L:L,"MEDIUM") | R3: =COUNTIFS(K:K,"PASS",L:L,"LOW")
A4: Created By | B4: KIMA | N4: FAIL | O4: =COUNTIF(K:K,"FAIL") | P4: =COUNTIFS(K:K,"FAIL",L:L,"HIGH") | Q4: =COUNTIFS(K:K,"FAIL",L:L,"MEDIUM") | R4: =COUNTIFS(K:K,"FAIL",L:L,"LOW")
A5: Date of Creation | B5: 46170 | N5: PENDING | O5: =COUNTIF(K:K,"PENDING") | P5: =COUNTIFS(K:K,"PENDING",L:L,"HIGH") | Q5: =COUNTIFS(K:K,"PENDING",L:L,"MEDIUM") | R5: =COUNTIFS(K:K,"PENDING",L:L,"LOW")
A6: Date of Review | B6: 46170
A8: TEST CASE ID | B8: TEST SCENARIO | C8: TEST CASE | D8: TEST CATEGORY | E8: PRE-CONDITION | F8: TEST STEPS | G8: TEST DATA | H8: EXPECTED RESULTS | I8: POST CONDITION | J8: ACTUAL RESULT | K8: STATUS | L8: PRIORITY | M8: TESTER | N8: TEST DATE | O8: DEVICE | P8: BROWSER | Q8: ISSUE LINK | R8: COMMENT | S8: Run
A9: TC_001 | B9: Transfer | C9: The Transfer hub offers all different types of transfer options | D9: Positive | E9: User is on Transfer page | F9: -Given I log into the UMPay application with valid email credentials using "<row>" of "<excelSheetName>" of "<excelFileName>" -When I open the Transfer hub -Then the Transfer hub should offer the route "UMPay to Existing template" -And the Transfer hub should offer the route "UMPay to UMPay Wallet" -And the Transfer hub should offer the route "UnionPay China" -And the Transfer hub should offer the route "UnionPay Global" -And the Transfer hub should offer the route "Transfer to Alipay" -And the Transfer hub should offer the route "Transfer to Wechat" | G9: Valid UMPay User | H9: User should be able to see all options | I9: User is still on Transfer page | J9: User can see all options | K9: PASS | L9: HIGH | M9: KIMA | O9: Window OS | P9: Edge | S9: Run
A10: TC_002 | B10: Transfer | C10: A payment option under maintenance should not open | D10: Positive | E10: User is on Transfer page | F10: -Given I log into the UMPay application with valid email credentials using "1" of "sheet1" of "Transfer_TestData.xlsx" -When I open the Transfer hub -Then the route "<route>" should be marked as under maintenance -When I take the "<route>" route from the Transfer hub -Then the app should say the service is unavailable | G10: Valid UMPay User | H10: User should not be able to open payment option under maintenance | I10: User is still on Transfer page | J10: User can not open payment option under maintenance | K10: PASS | L10: HIGH | M10: KIMA | O10: Window OS | P10: Edge | S10: Run
A11: TC_003 | B11: Transfer | C11: A wallet transfer cannot go forward from an empty form | D11: Negative | E11: User is on Transfer page | F11: -Given I log into the UMPay application with valid email credentials using "<row>" of "<excelSheetName>" of "<excelFileName>" -When I open the Transfer hub -And I take the "UMPay to UMPay Wallet" route from the Transfer hub -Then the UMPay wallet transfer form should be shown -And the wallet transfer should not be ready to continue | G11: Valid UMPay User | H11: User should not be able to perform transfer | I11: User is still on Transfer page | J11: User can not perform transfer | K11: PASS | L11: HIGH | M11: KIMA | O11: Window OS | P11: Edge | S11: Run
A12: TC_004 | B12: Transfer | C12: A wallet transfer is refused when nobody holds the mobile number | D12: Negative | E12: User is on Transfer page | F12: -Given I log into the UMPay application with valid email credentials using "<row>" of "<excelSheetName>" of "<excelFileName>" -When I open the Transfer hub -And I take the "UMPay to UMPay Wallet" route from the Transfer hub -Then the UMPay wallet transfer form should be shown -And the wallet form should keep the amount and remark locked -When I give the recipient's phone number in "<row>" of "<excelSheetName>" of "<excelFileName>" -Then the form should say the recipient does not exist -And the wallet form should keep the amount and remark locked -And the wallet transfer should not be ready to continue | G12: Valid UMPay User | H12: User should not be able to perform transfer | I12: User is still on Transfer page | J12: User can not perform transfer | K12: PASS | L12: HIGH | M12: KIMA | O12: Window OS | P12: Edge | S12: Run
A13: TC_005 | B13: Transfer | C13: A recipient nobody holds is refused when named by ID | D13: Negative | E13: User is on Transfer page | F13: -Given I log into the UMPay application with valid email credentials using "<row>" of "<excelSheetName>" of "<excelFileName>" -When I open the Transfer hub -And I take the "UMPay to UMPay Wallet" route from the Transfer hub -Then the UMPay wallet transfer form should be shown -When I name the recipient by "ID" -And I give the recipient's "ID" from "<row>" of "<excelSheetName>" of "<excelFileName>" -Then the form should say the recipient does not exist -And the wallet form should keep the amount and remark locked -And the wallet transfer should not be ready to continue | G13: Valid UMPay User | H13: User should not be able to perform transfer | I13: User is still on Transfer page | J13: User can not perform transfer | K13: PASS | L13: HIGH | M13: KIMA | O13: Window OS | P13: Edge | S13: Run
A14: TC_006 | B14: Transfer | C14: A recipient nobody holds is refused when named by Email | D14: Negative | E14: User is on Transfer page | F14: -Given I log into the UMPay application with valid email credentials using "<row>" of "<excelSheetName>" of "<excelFileName>" -When I open the Transfer hub -And I take the "UMPay to UMPay Wallet" route from the Transfer hub -Then the UMPay wallet transfer form should be shown -When I name the recipient by "EMAIL" -And I give the recipient's "EMAIL" from "<row>" of "<excelSheetName>" of "<excelFileName>" -Then the form should say the recipient does not exist -And the wallet form should keep the amount and remark locked -And the wallet transfer should not be ready to continue | G14: Valid UMPay User | H14: User should not be able to perform transfer | I14: User is still on Transfer page | J14: User can not perform transfer | K14: PASS | L14: HIGH | M14: KIMA | O14: Window OS | P14: Edge | S14: Run
A15: TC_007 | B15: Transfer | C15: A wallet transfer is sent to a recipient named by ID | D15: Positive | E15: User is on Transfer page | F15: -Given I log into the UMPay application with valid email credentials using "<row>" of "<excelSheetName>" of "<excelFileName>" -When I open the Transfer hub -And I take the "UMPay to UMPay Wallet" route from the Transfer hub -Then the UMPay wallet transfer form should be shown -And the wallet form should keep the amount and remark locked -When I name the recipient by "ID" -And I give the recipient's "ID" from "<row>" of "<excelSheetName>" of "<excelFileName>" -Then the form should find the recipient -When I enter the amount in "<row>" of "<excelSheetName>" of "<excelFileName>" to send -Then the wallet transfer should be ready to continue -When I send the wallet transfer, which moves real money -Then the wallet transfer should go through | G15: Valid UMPay User | H15: User should be able to perform transfer | I15: User is still on Transfer page | J15: User can perform transfer | K15: PASS | L15: HIGH | M15: KIMA | O15: Window OS | P15: Edge | S15: Run
A16: TC_008 | B16: Transfer | C16: A wallet transfer is sent to a recipient named by Email | D16: Positive | E16: User is on Transfer page | F16: -Given I log into the UMPay application with valid email credentials using "<row>" of "<excelSheetName>" of "<excelFileName>" -When I open the Transfer hub -And I take the "UMPay to UMPay Wallet" route from the Transfer hub -Then the UMPay wallet transfer form should be shown -And the wallet form should keep the amount and remark locked -When I name the recipient by "EMAIL" -And I give the recipient's "EMAIL" from "<row>" of "<excelSheetName>" of "<excelFileName>" -Then the form should find the recipient -When I enter the amount in "<row>" of "<excelSheetName>" of "<excelFileName>" to send -Then the wallet transfer should be ready to continue -When I send the wallet transfer, which moves real money -Then the wallet transfer should go through | G16: Valid UMPay User | H16: User should be able to perform transfer | I16: User is still on Transfer page | J16: User can perform transfer | K16: PASS | L16: HIGH | M16: KIMA | O16: Window OS | P16: Edge | S16: Run
A17: TC_009 | B17: Transfer | C17: A wallet transfer is sent to a recipient named by Mobile | D17: Positive | E17: User is on Transfer page | F17: -Given I log into the UMPay application with valid email credentials using "<row>" of "<excelSheetName>" of "<excelFileName>" -When I open the Transfer hub -And I take the "UMPay to UMPay Wallet" route from the Transfer hub -Then the UMPay wallet transfer form should be shown -And the wallet form should keep the amount and remark locked -When I name the recipient by "MOBILE" -And I give the recipient's "MOBILE" from "<row>" of "<excelSheetName>" of "<excelFileName>" -Then the form should find the recipient -When I enter the amount in "<row>" of "<excelSheetName>" of "<excelFileName>" to send -Then the wallet transfer should be ready to continue -When I send the wallet transfer, which moves real money -Then the wallet transfer should go through | G17: Valid UMPay User | H17: User should be able to perform transfer | I17: User is still on Transfer page | J17: User can perform transfer | K17: PASS | L17: HIGH | M17: KIMA | O17: Window OS | P17: Edge | S17: Run
A18: TC_010 | B18: Transfer | C18: A UnionPay China transfer from the Transfer page converts and is sent | D18: Positive | E18: User is on Transfer page | F18: -Given I log into the UMPay application with valid email credentials using "<row>" of "<excelSheetName>" of "<excelFileName>" -When I open the Transfer hub -And I take the "UnionPay China" route from the Transfer hub -Then the UnionPay amount form should be shown -And the UnionPay form should state "Limit Min" -And the UnionPay form should state "Limit Max" -And the UnionPay form should offer a converted amount -When I enter the stated minimum as the UnionPay amount -Then the converted amount should be worked out -And the UnionPay transfer should be ready to continue -When I go on to the receiver step -And I send it to the saved receiver in "<row>" of "<excelSheetName>" of "<excelFileName>", which moves real money -Then the transfer should go through | G18: Valid UMPay User | H18: User should be able to perform transfer | I18: User is still on Transfer page | J18: User can perform transfer | K18: PASS | L18: HIGH | M18: KIMA | O18: Window OS | P18: Edge | S18: Run
A19: TC_011 | B19: Transfer | C19: A UnionPay Global transfer from the Transfer page does not convert and is sent | D19: Positive | E19: User is on Transfer page | F19: -Given I log into the UMPay application with valid email credentials using "<row>" of "<excelSheetName>" of "<excelFileName>" -When I open the Transfer hub -And I take the "UnionPay Global" route from the Transfer hub -Then the UnionPay amount form should be shown -And the UnionPay form should state "Limit Min" -And the UnionPay form should state "Limit Max" -And the UnionPay form should not offer a converted amount -When I enter the stated minimum as the UnionPay amount -Then the UnionPay transfer should be ready to continue -When I go on to the receiver step -And I send it to the saved receiver in "<row>" of "<excelSheetName>" of "<excelFileName>", which moves real money -Then the transfer should go through | G19: Valid UMPay User | H19: User should be able to perform transfer | I19: User is still on Transfer page | J19: User can perform transfer | K19: PASS | L19: HIGH | M19: KIMA | O19: Window OS | P19: Edge | S19: Run
A20: TC_012 | B20: Transfer | C20: The Existing template route lists the destinations saved on the account | D20: Positive | E20: User is on Transfer page | F20: -Given I log into the UMPay application with valid email credentials using "<row>" of "<excelSheetName>" of "<excelFileName>" -When I open the Transfer hub -And I take the "UMPay to Existing template" route from the Transfer hub -Then the saved templates should be listed -And every saved template should mask the account it pays | G20: Valid UMPay User | H20: User should be able to see templates | I20: User is still on Transfer page | J20: User can see templates | K20: PASS | L20: HIGH | M20: KIMA | O20: Window OS | P20: Edge | S20: Run
A21: TC_013 | B21: Transfer | C21: A transfer to a saved template is sent | D21: Positive | E21: User is on Transfer page | F21: -Given I log into the UMPay application with valid email credentials using "<row>" of "<excelSheetName>" of "<excelFileName>" -When I open the Transfer hub -And I take the "UMPay to Existing template" route from the Transfer hub -Then the saved templates should be listed -When I choose the saved template in "<row>" of "<excelSheetName>" of "<excelFileName>" -Then the UnionPay amount form should be shown -And the transfer should be going to the account in "<row>" of "<excelSheetName>" of "<excelFileName>" -When I enter the stated minimum as the UnionPay amount -And I send the transfer, which moves real money -Then the transfer should be accepted | G21: Valid UMPay User | H21: User should be able to see templates | I21: User is still on Transfer page | J21: User can see templates | K21: PASS | L21: HIGH | M21: KIMA | O21: Window OS | P21: Edge | S21: Run

Sheet Convert
A1: Project Name | B1: UMPay
A2: Module/Feature Name | B2: Transfer | P2: HIGH | Q2: MEDIUM | R2: LOW
A3: Reference Document | N3: PASS | O3: =COUNTIF(K:K,"PASS") | P3: =COUNTIFS(K:K,"PASS",L:L,"HIGH") | Q3: =COUNTIFS(K:K,"PASS",L:L,"MEDIUM") | R3: =COUNTIFS(K:K,"PASS",L:L,"LOW")
A4: Created By | B4: KIMA | N4: FAIL | O4: =COUNTIF(K:K,"FAIL") | P4: =COUNTIFS(K:K,"FAIL",L:L,"HIGH") | Q4: =COUNTIFS(K:K,"FAIL",L:L,"MEDIUM") | R4: =COUNTIFS(K:K,"FAIL",L:L,"LOW")
A5: Date of Creation | B5: 46170 | N5: PENDING | O5: =COUNTIF(K:K,"PENDING") | P5: =COUNTIFS(K:K,"PENDING",L:L,"HIGH") | Q5: =COUNTIFS(K:K,"PENDING",L:L,"MEDIUM") | R5: =COUNTIFS(K:K,"PENDING",L:L,"LOW")
A6: Date of Review | B6: 46170
A8: TEST CASE ID | B8: TEST SCENARIO | C8: TEST CASE | D8: TEST CATEGORY | E8: PRE-CONDITION | F8: TEST STEPS | G8: TEST DATA | H8: EXPECTED RESULTS | I8: POST CONDITION | J8: ACTUAL RESULT | K8: STATUS | L8: PRIORITY | M8: TESTER | N8: TEST DATE | O8: DEVICE | P8: BROWSER | Q8: ISSUE LINK | R8: COMMENT | S8: Run
A9: TC_001 | B9: Convert | C9: Money is converted between two wallets | D9: Positive | E9: User is on Admin Team Page. | F9: -Given I log into the UMPay application with valid email credentials using "<row>" of "<excelSheetName>" of "<excelFileName>" -When I navigate to the Convert page -And I convert the amount in "<row>" of "<excelSheetName>" of "<excelFileName>" -Then the conversion should be confirmed with the message in "<row>" of "<excelSheetName>" of "<excelFileName>" -And the source wallet balance should have gone down by the converted amount | G9: Valid UMPay user | H9: User should be able to convert money between wallets | I9: User is still on convert page | J9: User can convert money between wallets | K9: PASS | L9: HIGH | M9: KIMA | O9: Window OS | P9: Edge | S9: Run
A10: TC_002 | B10: Convert | C10: Every wallet converts into every other wallet | D10: Positive | E10: User is on Admin Team Page. | F10: -Given I log into the UMPay application with valid email credentials using "<row>" of "<excelSheetName>" of "<excelFileName>" -When I navigate to the Convert page -Then converting the amount in "<row>" of "<excelSheetName>" of "<excelFileName>" into every other wallet, ending with "HKD", should succeed | G10: Valid UMPay user | H10: User should be able to convert money between each wallet pair | I10: User is still on convert page | J10: User can convert money between each wallet pair | K10: PASS | L10: HIGH | M10: KIMA | O10: Window OS | P10: Edge | S10: Run
A11: TC_003 | B11: Convert | C11: The convert form offers a wallet for every currency the account holds | D11: Positive | E11: User is on Admin Team Page. | F11: -Given I log into the UMPay application with valid email credentials using "<row>" of "<excelSheetName>" of "<excelFileName>" -When I navigate to the Convert page -Then the convert currency list should offer "BDT, BRL, HKD, IDR, MXN, MYR, PHP, THB, USD, VND" | G11: Valid UMPay user | H11: User should be able to see all wallets | I11: User is still on convert page | J11: User can all wallets | K11: PASS | L11: HIGH | M11: KIMA | O11: Window OS | P11: Edge | S11: Run
A12: TC_004 | B12: Convert | C12: The amount box holds a conversion to the pair's stated limits | D12: Positive | E12: User is on Admin Team Page. | F12: -GGiven I log into the UMPay application with valid email credentials using "<row>" of "<excelSheetName>" of "<excelFileName>" -When I navigate to the Convert page -And I choose to convert from "HKD" to "PHP" -And I enter one below the stated minimum as the convert amount -Then the convert amount should be refused with "Please input an amount of limit min or above!" -When I enter one above the stated maximum as the convert amount -Then the convert amount should be refused with "Please input an amount of limit max or below!" -When I enter the stated minimum as the convert amount -Then the convert amount should be accepted -And the form should offer to convert | G12: Valid UMPay user | H12: All the set limits should work as expected | I12: User is still on convert page | J12: All the set limits are working as expected | K12: PASS | L12: HIGH | M12: KIMA | O12: Window OS | P12: Edge | S12: Run
A13: TC_005 | B13: Convert | C13: The conversion history opens from the Convert page | D13: Positive | E13: User is on Admin Team Page. | F13: -Given I log into the UMPay application with valid email credentials using "<row>" of "<excelSheetName>" of "<excelFileName>" -When I navigate to the Convert page -And I open the conversion history -Then the conversion history should be shown -And every conversion listed should name an amount, a time, what it became and the rate | G13: Valid UMPay user | H13: User should be able to access history | I13: User is still on convert page | J13: User can access history | K13: PASS | L13: HIGH | M13: KIMA | O13: Window OS | P13: Edge | S13: Run
